[ 2024-10-18 01:01:51,235 ] 97 werkzeug - INFO - [31m[1mWARNING: This is a development server. Do not use it in a production deployment. Use a production WSGI server instead.[0m
 * Running on all addresses (0.0.0.0)
 * Running on http://127.0.0.1:80
 * Running on http://192.168.1.4:80
[ 2024-10-18 01:01:51,235 ] 97 werkzeug - INFO - [33mPress CTRL+C to quit[0m
[ 2024-10-18 01:03:03,839 ] 97 werkzeug - INFO - 127.0.0.1 - - [18/Oct/2024 01:03:03] "GET / HTTP/1.1" 200 -
[ 2024-10-18 01:03:03,898 ] 97 werkzeug - INFO - 127.0.0.1 - - [18/Oct/2024 01:03:03] "[33mGET /favicon.ico HTTP/1.1[0m" 404 -
[ 2024-10-18 01:03:57,339 ] 97 werkzeug - INFO - 127.0.0.1 - - [18/Oct/2024 01:03:57] "GET /predictdata HTTP/1.1" 200 -
[ 2024-10-18 01:04:13,851 ] 838 app - ERROR - Exception on /predictdata [POST]
Traceback (most recent call last):
  File "c:\code\mlproject\src\pipeline\predict_pipeline.py", line 18, in predict
    data_scaled=preprocessor.transform(features)
                ^^^^^^^^^^^^^^^^^^^^^^^^^^^^^^^^
  File "C:\Users\saksh\anaconda3\Lib\site-packages\sklearn\utils\_set_output.py", line 295, in wrapped
    data_to_wrap = f(self, X, *args, **kwargs)
                   ^^^^^^^^^^^^^^^^^^^^^^^^^^^
  File "C:\Users\saksh\anaconda3\Lib\site-packages\sklearn\compose\_column_transformer.py", line 1014, in transform
    Xs = self._call_func_on_transformers(
         ^^^^^^^^^^^^^^^^^^^^^^^^^^^^^^^^
  File "C:\Users\saksh\anaconda3\Lib\site-packages\sklearn\compose\_column_transformer.py", line 823, in _call_func_on_transformers
    return Parallel(n_jobs=self.n_jobs)(jobs)
           ^^^^^^^^^^^^^^^^^^^^^^^^^^^^^^^^^^
  File "C:\Users\saksh\anaconda3\Lib\site-packages\sklearn\utils\parallel.py", line 67, in __call__
    return super().__call__(iterable_with_config)
           ^^^^^^^^^^^^^^^^^^^^^^^^^^^^^^^^^^^^^^
  File "C:\Users\saksh\anaconda3\Lib\site-packages\joblib\parallel.py", line 1918, in __call__
    return output if self.return_generator else list(output)
                                                ^^^^^^^^^^^^
  File "C:\Users\saksh\anaconda3\Lib\site-packages\joblib\parallel.py", line 1847, in _get_sequential_output
    res = func(*args, **kwargs)
          ^^^^^^^^^^^^^^^^^^^^^
  File "C:\Users\saksh\anaconda3\Lib\site-packages\sklearn\utils\parallel.py", line 129, in __call__
    return self.function(*args, **kwargs)
           ^^^^^^^^^^^^^^^^^^^^^^^^^^^^^^
  File "C:\Users\saksh\anaconda3\Lib\site-packages\sklearn\pipeline.py", line 1283, in _transform_one
    res = transformer.transform(X, **params.transform)
          ^^^^^^^^^^^^^^^^^^^^^^^^^^^^^^^^^^^^^^^^^^^^
  File "C:\Users\saksh\anaconda3\Lib\site-packages\sklearn\pipeline.py", line 905, in transform
    Xt = transform.transform(Xt, **routed_params[name].transform)
         ^^^^^^^^^^^^^^^^^^^^^^^^^^^^^^^^^^^^^^^^^^^^^^^^^^^^^^^^
  File "C:\Users\saksh\anaconda3\Lib\site-packages\sklearn\utils\_set_output.py", line 295, in wrapped
    data_to_wrap = f(self, X, *args, **kwargs)
                   ^^^^^^^^^^^^^^^^^^^^^^^^^^^
  File "C:\Users\saksh\anaconda3\Lib\site-packages\sklearn\preprocessing\_encoders.py", line 1032, in transform
    if self._drop_idx_after_grouping is not None:
       ^^^^^^^^^^^^^^^^^^^^^^^^^^^^^
AttributeError: 'OneHotEncoder' object has no attribute '_drop_idx_after_grouping'

During handling of the above exception, another exception occurred:

Traceback (most recent call last):
  File "C:\Users\saksh\anaconda3\Lib\site-packages\flask\app.py", line 1473, in wsgi_app
    response = self.full_dispatch_request()
               ^^^^^^^^^^^^^^^^^^^^^^^^^^^^
  File "C:\Users\saksh\anaconda3\Lib\site-packages\flask\app.py", line 882, in full_dispatch_request
    rv = self.handle_user_exception(e)
         ^^^^^^^^^^^^^^^^^^^^^^^^^^^^^
  File "C:\Users\saksh\anaconda3\Lib\site-packages\flask\app.py", line 880, in full_dispatch_request
    rv = self.dispatch_request()
         ^^^^^^^^^^^^^^^^^^^^^^^
  File "C:\Users\saksh\anaconda3\Lib\site-packages\flask\app.py", line 865, in dispatch_request
    return self.ensure_sync(self.view_functions[rule.endpoint])(**view_args)  # type: ignore[no-any-return]
           ^^^^^^^^^^^^^^^^^^^^^^^^^^^^^^^^^^^^^^^^^^^^^^^^^^^^^^^^^^^^^^^^^
  File "c:\code\mlproject\app.py", line 36, in predict_datapoint
    results=predict_pipeline.predict(pred_df)
            ^^^^^^^^^^^^^^^^^^^^^^^^^^^^^^^^^
  File "c:\code\mlproject\src\pipeline\predict_pipeline.py", line 23, in predict
    raise CustomException(e,sys)
src.exception.CustomException: Error occured in python script name [c:\code\mlproject\src\pipeline\predict_pipeline.py] line number [18] error message['OneHotEncoder' object has no attribute '_drop_idx_after_grouping']
[ 2024-10-18 01:04:13,890 ] 97 werkzeug - INFO - 127.0.0.1 - - [18/Oct/2024 01:04:13] "[35m[1mPOST /predictdata HTTP/1.1[0m" 500 -
